Workbook

Sheet Cost Forecast
A1: GoLuna — Path C (Anzil) Month-by-Month Cost Forecast (USD)
A2: Anzil engagement hard-capped at $100K over the 3-month pilot (M2–M4) · 1M SEK dedicated to Brazil/Anzil · clipping + influencer activation removed · M2 kill checkpoint (decision 2026-06-11). Benchmarks, not GoLuna-measured data — verify at M4.
A4: Assumptions
A5: FX (SEK per USD) | B5: 10.5
A6: Working budget (2.5M SEK, USD) | B6: =2500000/B5 -> 238095.24
A7: Brazil/Anzil envelope (1M SEK, USD) | B7: =1000000/B5 -> 95238.095
A8: Anzil management fee (% of media) | B8: 0.15
A9: Anzil contract hard cap (USD) | B9: 100000
A11: Line | B11: M1 | C11: M2 | D11: M3 | E11: M4 | F11: M5 | G11: M6 | H11: M7 | I11: M8 | J11: M9 | K11: M10 | L11: M11 | M11: M12 | N11: Total
A12: Salaries (T+O+G) | B12: 5000 | C12: 5000 | D12: 5000 | E12: 5000 | F12: 5000 | G12: 5000 | H12: 5000 | I12: 5000 | J12: 5000 | K12: 5000 | L12: 5000 | M12: 5000 | N12: =SUM(B12:M12) -> 60000
A13: X VIP Transfer Method | B13: 0 | C13: 1143 | D13: 1143 | E13: 1143 | F13: 1143 | G13: 1143 | H13: 1143 | I13: 1143 | J13: 1143 | K13: 1143 | L13: 1143 | M13: 1143 | N13: =SUM(B13:M13) -> 12573
A14: Cubeia AWS hosting | B14: 1836 | C14: 1836 | D14: 1836 | E14: 1836 | F14: 1836 | G14: 1836 | H14: 1836 | I14: 1836 | J14: 1836 | K14: 1836 | L14: 1836 | M14: 1836 | N14: =SUM(B14:M14) -> 22032
A15: Customer.io (Cubeia App. B) | B15: 324 | C15: 324 | D15: 324 | E15: 324 | F15: 324 | G15: 324 | H15: 324 | I15: 324 | J15: 324 | K15: 324 | L15: 324 | M15: 324 | N15: =SUM(B15:M15) -> 3888
A16: Freshchat (Cubeia App. B) | B16: 0 | C16: 54 | D16: 54 | E16: 54 | F16: 54 | G16: 54 | H16: 54 | I16: 54 | J16: 54 | K16: 54 | L16: 54 | M16: 54 | N16: =SUM(B16:M16) -> 594
A17: Cubeia platform min (from M7) | B17: 0 | C17: 0 | D17: 0 | E17: 0 | F17: 0 | G17: 0 | H17: 5400 | I17: 5400 | J17: 5400 | K17: 5400 | L17: 5400 | M17: 5400 | N17: =SUM(B17:M17) -> 32400
A18: Security stack subs | B18: 281 | C18: 281 | D18: 281 | E18: 281 | F18: 281 | G18: 281 | H18: 281 | I18: 281 | J18: 281 | K18: 281 | L18: 281 | M18: 281 | N18: =SUM(B18:M18) -> 3372
A19: Claude Max | B19: 200 | C19: 200 | D19: 200 | E19: 200 | F19: 200 | G19: 200 | H19: 200 | I19: 200 | J19: 200 | K19: 200 | L19: 200 | M19: 200 | N19: =SUM(B19:M19) -> 2400
A20: Security stack — hardware (one-time) | B20: 1652 | C20: 0 | D20: 0 | E20: 0 | F20: 0 | G20: 0 | H20: 0 | I20: 0 | J20: 0 | K20: 0 | L20: 0 | M20: 0 | N20: =SUM(B20:M20) -> 1652
A21: Costa Rica corp (2026) | B21: 6858 | C21: 0 | D21: 0 | E21: 0 | F21: 0 | G21: 0 | H21: 0 | I21: 0 | J21: 0 | K21: 0 | L21: 0 | M21: 0 | N21: =SUM(B21:M21) -> 6858
A22: Designer (casino design) | B22: 4800 | C22: 0 | D22: 0 | E22: 0 | F22: 0 | G22: 0 | H22: 0 | I22: 0 | J22: 0 | K22: 0 | L22: 0 | M22: 0 | N22: =SUM(B22:M22) -> 4800
A23: Betby setup (sportsbook) | B23: 3000 | C23: 0 | D23: 0 | E23: 0 | F23: 0 | G23: 0 | H23: 0 | I23: 0 | J23: 0 | K23: 0 | L23: 0 | M23: 0 | N23: =SUM(B23:M23) -> 3000
... A27: Anzil media — Meta+WhatsApp (M2–M4) | B27: 0 | C27: 15000 | D27: 25000 | E27: 29000 | F27: 0 | G27: 0 | H27: 0 | I27: 0 | J27: 0 | K27: 0 | L27: 0 | M27: 0 | N27: =SUM(B27:M27) -> 69000
A28: Anzil management (15% of media) | B28: =B27*$B$8 -> 0 | C28: =C27*$B$8 -> 2250 | D28: =D27*$B$8 -> 3750 | E28: =E27*$B$8 -> 4350 | F28: =F27*$B$8 -> 0 | G28: =G27*$B$8 -> 0 | H28: =H27*$B$8 -> 0 | I28: =I27*$B$8 -> 0 | ... M28: =M27*$B$8 -> 0 | N28: =SUM(B28:M28) -> 10350
A29: MARKETING / ANZIL — monthly total (setup + retainer + media + mgmt) | B29: =SUM(B25:B28) -> 3240 | C29: =SUM(C25:C28) -> 18870 | D29: =SUM(D25:D28) -> 30370 | E29: =SUM(E25:E28) -> 34970 | F29: =SUM(F25:F28) -> 0 | G29: =SUM(G25:G28) -> 0 | H29: =SUM(H25:H28) -> 0 | I29: =SUM(I25:I28) -> 0 | ... N29: =SUM(N25:N28) -> 87450
A30: GoLuna fixed — monthly total (salaries, platform, security, one-times) | B30: =SUM(B12:B24) -> 24427 | C30: =SUM(C12:C24) -> 9314 | D30: =SUM(D12:D24) -> 9314 | E30: =SUM(E12:E24) -> 9314 | F30: =SUM(F12:F24) -> 9314 | G30: =SUM(G12:G24) -> 9314 | H30: =SUM(H12:H24) -> 14714 | I30: =SUM(I12:I24) -> 14714 | ... N30: =SUM(N12:N24) -> 159281
A31: Monthly total (fixed + marketing) | B31: =B29+B30 -> 27667 | C31: =C29+C30 -> 28184 | D31: =D29+D30 -> 39684 | E31: =E29+E30 -> 44284 | F31: =F29+F30 -> 9314 | G31: =G29+G30 -> 9314 | H31: =H29+H30 -> 14714 | I31: =I29+I30 -> 14714 | ... N31: =N29+N30 -> 246731
A32: Cumulative | B32: =B31 -> 27667 | C32: =B32+C31 -> 55851 | D32: =C32+D31 -> 95535 | E32: =D32+E31 -> 139819 | F32: =E32+F31 -> 149133 | G32: =F32+G31 -> 158447 | H32: =G32+H31 -> 173161 | I32: =H32+I31 -> 187875 | J32: =I32+J31 -> 202589 | ... M32: =L32+M31 -> 246731
A33: Operating budget remaining (vs 2.5M SEK) | B33: =$B$6-B32 -> 210428.24 | C33: =$B$6-C32 -> 182244.24 | D33: =$B$6-D32 -> 142560.24 | E33: =$B$6-E32 -> 98276.238 | F33: =$B$6-F32 -> 88962.238 | G33: =$B$6-G32 -> 79648.238 | H33: =$B$6-H32 -> 64934.238 | I33: =$B$6-I32 -> 50220.238 | ... M33: =$B$6-M32 -> -8635.7619
A36: Anzil engagement summary
A37: Anzil committed total (setup + retainer + media + mgmt) | B37: =N25+N26+N27+N28 -> 87450
A38: Brazil/Anzil envelope (1M SEK) | B38: =B7 -> 95238.095
A39: Headroom vs envelope (WhatsApp/PIX fees, TBD) | B39: =B7-B37 -> 7788.0952
A40: Contract hard cap | B40: =B9 -> 100000
A41: Headroom vs hard cap | B41: =B9-B37 -> 12550
A42: Sunk if cut at M2 checkpoint (setup + M2 retainer/media/mgmt) | B42: =B25+C26+C27+C28 -> 22110
A43: Never deployed if cut at M2 | B43: =B37-B42 -> 65340
A44: Paid if cut after 2 live months (end of M3) | B44: =B42+D26+D27+D28 -> 52480

Sheet Revenue Targets
A1: GoLuna — Path C Revenue Targets by Month (what to optimize for)
A2: NEED = ~28% retention (the break-even line: M4-exit run-rate covers the M7+ fixed burn). OPTIMIZE = ~39% retention (the flywheel compounds). Basis: ARPU $30/mo (Brazil regulated avg), CAC $20 (Anzil quote), net contribution 51.5% of GGR (incl. ~5% high-estimate PIX fee). Market benchmarks, not GoLuna data — recalibrate with real cohorts at M2–M3.
A4: Assumptions
A5: ARPU (GGR / active / month) | B5: 30
A6: CAC per FTD (Anzil quote $12–25) | B6: 20
A7: NGR (GGR − bonuses 25%) | B7: 0.75
A8: Net contribution (after all variable, incl. PIX high-est.) | B8: 0.515
A9: Retention — NEED (break-even line) | B9: 0.28
A10: Retention — OPTIMIZE (compounding) | B10: 0.39
A11: M7+ fixed run-rate (from Cost Forecast) | B11: ='Cost Forecast'!H31 -> 14714
A13: PROFIT — AT A GLANCE
A14: Scenario | B14: Pilot M1–M4 (the investment) | C14: M5–M6 / mo | D14: M7+ / mo | E14: Cumulative at M6
A15: NEED — break-even (~28% ret.) | B15: =SUM(B31:E31) -> -74620 | C15: =F31 -> 5610.7 | D15: =H31 -> 210.7 | E15: =G32 -> -63398.6
A16: OPTIMIZE — compounding (~39% ret.) | B16: =SUM(B40:E40) -> -69946.375 | C16: =F40 -> 11473.975 | D16: =H40 -> 6073.975 | E16: =G41 -> -46998.425
A18: Read: the pilot is an investment (red) in both scenarios. At the NEED line the machine reaches break-even from M7 (profit ≈ $0/mo — that is the definition of the line). At the OPTIMIZE line the same spend returns ~+$6K/mo from M7 to reinvest. Green = profit, red = loss.
A20: Metric | B20: M1 (onboard) | C20: M2 (pilot 1) | D20: M3 (pilot 2) | E20: M4 (pilot 3 · gate) | F20: M5 | G20: M6 | H20: M7+ /mo
A21: Anzil media spend | B21: ='Cost Forecast'!B27 -> 0 | C21: ='Cost Forecast'!C27 -> 15000 | D21: ='Cost Forecast'!D27 -> 25000 | E21: ='Cost Forecast'!E27 -> 29000 | F21: ='Cost Forecast'!F27 -> 0 | G21: ='Cost Forecast'!G27 -> 0 | H21: ='Cost Forecast'!H27 -> 0
A22: New FTDs (media ÷ CAC) | B22: =B21/$B$6 -> 0 | C22: =C21/$B$6 -> 750 | D22: =D21/$B$6 -> 1250 | E22: =E21/$B$6 -> 1450 | F22: =F21/$B$6 -> 0 | G22: =G21/$B$6 -> 0 | H22: =H21/$B$6 -> 0
A23: Cumulative FTDs (end of month) | B23: =B22 -> 0 | C23: =B23+C22 -> 750 | D23: =C23+D22 -> 2000 | E23: =D23+E22 -> 3450 | F23: =E23+F22 -> 3450 | G23: =F23+G22 -> 3450 | H23: =G23+H22 -> 3450
A25: NEED — break-even line (~28% retention)
A26: Active depositors | B26: =0 -> 0 | C26: =C22+$B$9*B23 -> 750 | D26: =D22+$B$9*C23 -> 1460 | E26: =E22+$B$9*D23 -> 2010 | F26: =$B$9*$E$23 -> 966 | G26: =$B$9*$E$23 -> 966 | H26: =$B$9*$E$23 -> 966
A27: Target GGR (actives × ARPU) | B27: =B26*$B$5 -> 0 | C27: =C26*$B$5 -> 22500 | D27: =D26*$B$5 -> 43800 | E27: =E26*$B$5 -> 60300 | F27: =F26*$B$5 -> 28980 | G27: =G26*$B$5 -> 28980 | H27: =H26*$B$5 -> 28980
A28: ≈ NGR (GGR − 25% bonuses) | B28: =B27*$B$7 -> 0 | C28: =C27*$B$7 -> 16875 | D28: =D27*$B$7 -> 32850 | E28: =E27*$B$7 -> 45225 | F28: =F27*$B$7 -> 21735 | G28: =G27*$B$7 -> 21735 | H28: =H27*$B$7 -> 21735
A29: Net contribution (51.5% of GGR) | B29: =B27*$B$8 -> 0 | C29: =C27*$B$8 -> 11587.5 | D29: =D27*$B$8 -> 22557 | E29: =E27*$B$8 -> 31054.5 | F29: =F27*$B$8 -> 14924.7 | G29: =G27*$B$8 -> 14924.7 | H29: =H27*$B$8 -> 14924.7
A30: Monthly cost (from Cost Forecast) | B30: ='Cost Forecast'!B31 -> 27667 | C30: ='Cost Forecast'!C31 -> 28184 | D30: ='Cost Forecast'!D31 -> 39684 | E30: ='Cost Forecast'!E31 -> 44284 | F30: ='Cost Forecast'!F31 -> 9314 | G30: ='Cost Forecast'!G31 -> 9314 | H30: ='Cost Forecast'!H31 -> 14714
A31: MONTHLY PROFIT / LOSS (net contribution − cost) | B31: =B29-B30 -> -27667 | C31: =C29-C30 -> -16596.5 | D31: =D29-D30 -> -17127 | E31: =E29-E30 -> -13229.5 | F31: =F29-F30 -> 5610.7 | G31: =G29-G30 -> 5610.7 | H31: =H29-H30 -> 210.7
A32: CUMULATIVE PROFIT / LOSS (M1–M6) | B32: =B31 -> -27667 | C32: =B32+C31 -> -44263.5 | D32: =C32+D31 -> -61390.5 | E32: =D32+E31 -> -74620 | F32: =E32+F31 -> -69009.3 | G32: =F32+G31 -> -63398.6 | H32: n/a
A34: OPTIMIZE — compounding (~39% retention)
A35: Active depositors | B35: =0 -> 0 | C35: =C22+$B$10*B23 -> 750 | D35: =D22+$B$10*C23 -> 1542.5 | E35: =E22+$B$10*D23 -> 2230 | F35: =$B$10*$E$23 -> 1345.5 | G35: =$B$10*$E$23 -> 1345.5 | H35: =$B$10*$E$23 -> 1345.5
A36: Target GGR (actives × ARPU) | B36: =B35*$B$5 -> 0 | C36: =C35*$B$5 -> 22500 | D36: =D35*$B$5 -> 46275 | E36: =E35*$B$5 -> 66900 | F36: =F35*$B$5 -> 40365 | G36: =G35*$B$5 -> 40365 | H36: =H35*$B$5 -> 40365
A37: ≈ NGR (GGR − 25% bonuses) | B37: =B36*$B$7 -> 0 | C37: =C36*$B$7 -> 16875 | D37: =D36*$B$7 -> 34706.25 | E37: =E36*$B$7 -> 50175 | F37: =F36*$B$7 -> 30273.75 | G37: =G36*$B$7 -> 30273.75 | H37: =H36*$B$7 -> 30273.75
A38: Net contribution (51.5% of GGR) | B38: =B36*$B$8 -> 0 | C38: =C36*$B$8 -> 11587.5 | D38: =D36*$B$8 -> 23831.625 | E38: =E36*$B$8 -> 34453.5 | F38: =F36*$B$8 -> 20787.975 | G38: =G36*$B$8 -> 20787.975 | H38: =H36*$B$8 -> 20787.975
A39: Monthly cost (from Cost Forecast) | B39: ='Cost Forecast'!B31 -> 27667 | C39: ='Cost Forecast'!C31 -> 28184 | D39: ='Cost Forecast'!D31 -> 39684 | E39: ='Cost Forecast'!E31 -> 44284 | F39: ='Cost Forecast'!F31 -> 9314 | G39: ='Cost Forecast'!G31 -> 9314 | H39: ='Cost Forecast'!H31 -> 14714
A40: MONTHLY PROFIT / LOSS (net contribution − cost) | B40: =B38-B39 -> -27667 | C40: =C38-C39 -> -16596.5 | D40: =D38-D39 -> -15852.375 | E40: =E38-E39 -> -9830.5 | F40: =F38-F39 -> 11473.975 | G40: =G38-G39 -> 11473.975 | H40: =H38-H39 -> 6073.975
A41: CUMULATIVE PROFIT / LOSS (M1–M6) | B41: =B40 -> -27667 | C41: =B41+C40 -> -44263.5 | D41: =C41+D40 -> -60115.875 | E41: =D41+E40 -> -69946.375 | F41: =E41+F40 -> -58472.4 | G41: =F41+G40 -> -46998.425 | H41: n/a
A44: After-M4 states (exit run-rate vs the floor)
A45: Retention of ~3,450 pilot FTDs | B45: Active deps | C45: GGR / mo | D45: Net / mo (51.5%) | E45: vs M7+ run-rate | F45: Verdict
A46: 0.15 | B46: =A46*$E$23 -> 517.5 | C46: =B46*$B$5 -> 15525 | D46: =C46*$B$8 -> 7995.375 | E46: =D46-$B$11 -> -6718.625 | F46: KILL — bleeds
A47: 0.25 | B47: =A47*$E$23 -> 862.5 | C47: =B47*$B$5 -> 25875 | D47: =C47*$B$8 -> 13325.625 | E47: =D47-$B$11 -> -1388.375 | F47: Marginal — kill unless trending up
A48: 0.28 | B48: =A48*$E$23 -> 966 | C48: =B48*$B$5 -> 28980 | D48: =C48*$B$8 -> 14924.7 | E48: =D48-$B$11 -> 210.7 | F48: Break-even — the GO line
...
